Workbook

Sheet GA
A1: CROSSOVER RATE | B1: 0.9 | C1: 0.9 | D1: 0.9 | F1: CROSSOVER RATE | G1: 0.9 | H1: 0.9 | I1: 0.9 | K1: CROSSOVER RATE | L1: 0.9 | M1: 0.9 | N1: 0.9
A2: MURATION RATE | B2: 0.02 | C2: 0.11 | D2: 0.2 | F2: MURATION RATE | G2: 0.02 | H2: 0.11 | I2: 0.2 | K2: MURATION RATE | L2: 0.02 | M2: 0.11 | N2: 0.2
A3: ELITE COUNT | B3: 5 | C3: 2 | D3: 3 | F3: ELITE COUNT | G3: 5 | H3: 2 | I3: 3 | K3: ELITE COUNT | L3: 5 | M3: 2 | N3: 3
A4: GA | C4: D = 5 | F4: GA | H4: D = 30 | K4: GA | M4: D = 100
A5: Trial | B5: Sphere | C5: Rosenbrock | D5: Rastrigin | F5: Trial | G5: Sphere | H5: Rosenbrock | I5: Rastrigin | K5: Trial | L5: Sphere | M5: Rosenbrock | N5: Rastrigin
A6: 1 | B6: 2.0882574e-28 | C6: 0.50442469 | D6: 3.4108008 | F6: 1 | G6: 0.0002440925 | H6: 120.0778 | I6: 18.166277 | K6: 1 | L6: 156.94365 | M6: 101811.6 | N6: 445.18386
A7: 2 | B7: 1.7611012e-28 | C7: 1.4142679 | D7: 1.9861702 | F7: 2 | G7: 0.00061002692 | H7: 70.491593 | I7: 19.601562 | K7: 2 | L7: 59.417581 | M7: 76340.315 | N7: 435.19689
A8: 3 | B8: 2.850384e-29 | C8: 0.361166 | D8: 1.9861702 | F8: 3 | G8: 0.10019538 | H8: 46.511891 | I8: 17.739891 | K8: 3 | L8: 108.39474 | M8: 75880.051 | N8: 510.42456
A9: 4 | B9: 2.6545739e-28 | C9: 0.038457492 | D9: 1.9861702 | F9: 4 | G9: 0.00016497482 | H9: 235.05174 | I9: 21.520052 | K9: 4 | L9: 91.13726 | M9: 93916.92 | N9: 458.78413
A10: 5 | B10: 5.8018179e-28 | C10: 0.048453133 | D10: 1.9861702 | F10: 5 | G10: 0.0003427249 | H10: 80.021873 | I10: 21.124131 | K10: 5 | L10: 112.25012 | M10: 58910.472 | N10: 565.61323
A11: 6 | B11: 8.5225745e-29 | C11: 0.55188746 | D11: 1.9861702 | F11: 6 | G11: 8.4571413e-05 | H11: 80.935388 | I11: 21.934618 | K11: 6 | L11: 102.14056 | M11: 59810.846 | N11: 518.80476
A12: 7 | B12: 7.5696679e-29 | C12: 0.46216271 | D12: 1.9861702 | F12: 7 | G12: 4.9400648 | H12: 241.02524 | I12: 34.028468 | K12: 7 | L12: 186.02155 | M12: 100887.71 | N12: 586.70553
A13: 8 | B13: 6.9443177e-29 | C13: 0.10449277 | D13: 1.9861702 | F13: 8 | G13: 0.020832634 | H13: 29.642579 | I13: 26.436553 | K13: 8 | L13: 58.61895 | M13: 118934.84 | N13: 413.41644
A14: 9 | B14: 1.74167e-28 | C14: 1.2173611 | D14: 4.8354314 | F14: 9 | G14: 0.00051916608 | H14: 281.65176 | I14: 33.891852 | K14: 9 | L14: 167.4841 | M14: 47994.567 | N14: 512.21716
A15: 10 | B15: 5.5474603e-29 | C15: 0.65087918 | D15: 1.9861702 | F15: 10 | G15: 0.00039603648 | H15: 32.149069 | I15: 28.241277 | K15: 10 | L15: 150.4344 | M15: 184124.14 | N15: 442.08431
A16: 11 | B16: 1.2889465e-28 | C16: 0.55370811 | D16: 1.9861702 | F16: 11 | G16: 0.13433288 | H16: 151.1777 | I16: 40.157398 | K16: 11 | L16: 107.53879 | M16: 34312.875 | N16: 468.4514
A17: 12 | B17: 1.165994e-27 | C17: 0.57423569 | D17: 1.9861702 | F17: 12 | G17: 0.001076625 | H17: 103.70137 | I17: 17.877659 | K17: 12 | L17: 139.27169 | M17: 47584.676 | N17: 606.2862
... A55: 50 | B55: 2.6668695e-28 | C55: 1.2431219 | D55: 1.9861702 | F55: 50 | G55: 0.00041122076 | H55: 80.223492 | I55: 22.573301 | K55: 50 | L55: 45.055084 | M55: 67696.488 | N55: 439.04713
A56: AVG | B56: =AVERAGE(B6:B55) -> 3.038014e-25 | C56: =AVERAGE(C6:C55) -> 0.48835396 | D56: =AVERAGE(D6:D55) -> 2.3850667 | F56: AVG | G56: =AVERAGE(G6:G55) -> 0.55429475 | H56: =AVERAGE(H6:H55) -> 648.96258 | I56: =AVERAGE(I6:I55) -> 25.820841 | K56: AVG | L56: =AVERAGE(L6:L55) -> 115.15322 | M56: =AVERAGE(M6:M55) -> 90177.62 | N56: =AVERAGE(N6:N55) -> 524.19524
A57: MED | B57: =MEDIAN(B6:B55) -> 1.2000283e-28 | C57: =MEDIAN(C6:C55) -> 0.33267242 | D57: =MEDIAN(D6:D55) -> 1.9861702 | F57: MED | G57: =MEDIAN(G6:G55) -> 0.00065182041 | H57: =MEDIAN(H6:H55) -> 109.32052 | I57: =MEDIAN(I6:I55) -> 22.638741 | K57: MED | L57: =MEDIAN(L6:L55) -> 112.02579 | M57: =MEDIAN(M6:M55) -> 85501.9 | N57: =MEDIAN(N6:N55) -> 512.15859
A58: VAR_S | B58: =_xlfn.VAR.S(B6:B55) -> 3.1989718e-48 | C58: =_xlfn.VAR.S(C6:C55) -> 0.23731538 | D58: =_xlfn.VAR.S(D6:D55) -> 0.66603109 | F58: VAR_S | G58: =_xlfn.VAR.S(G6:G55) -> 2.75522 | H58: =_xlfn.VAR.S(H6:H55) -> 10446324 | I58: =_xlfn.VAR.S(I6:I55) -> 69.437994 | K58: VAR_S | L58: =_xlfn.VAR.S(L6:L55) -> 1949.7272 | M58: =_xlfn.VAR.S(M6:M55) -> 1.9613105e+09 | N58: =_xlfn.VAR.S(N6:N55) -> 6629.6156

Sheet PSO
A1: W | B1: 0.3 | C1: 0.3 | D1: 0.3 | F1: W | G1: 0.3 | H1: 0.3 | I1: 0.3 | K1: W | L1: 0.3 | M1: 0.3 | N1: 0.3
A2: C1 | B2: 2 | C2: 2 | D2: 2 | F2: C1 | G2: 2 | H2: 2 | I2: 2 | K2: C1 | L2: 2 | M2: 2 | N2: 2
A3: C2 | B3: 2 | C3: 2 | D3: 2 | F3: C2 | G3: 2 | H3: 2 | I3: 2 | K3: C2 | L3: 2 | M3: 2 | N3: 2
A4: PSO | C4: D = 5 | F4: PSO | H4: D = 30 | K4: PSO | M4: D = 100
A5: Trial | B5: Sphere | C5: Rosenbrock | D5: Rastrigin | F5: Trial | G5: Sphere | H5: Rosenbrock | I5: Rastrigin | K5: Trial | L5: Sphere | M5: Rosenbrock | N5: Rastrigin
A6: 1 | B6: 1.1666231e-61 | C6: 0.29367396 | D6: 4.8354314 | F6: 1 | G6: 2.1371876e-10 | H6: 25.829721 | I6: 38.995623 | K6: 1 | L6: 0.36852871 | M6: 245.63769 | N6: 186.45117
A7: 2 | B7: 1.0665049e-62 | C7: 0.27561381 | D7: 4.8354314 | F7: 2 | G7: 8.2657705e-11 | H7: 80.134189 | I7: 27.587958 | K7: 2 | L7: 0.42122904 | M7: 472.76733 | N7: 160.56325
A8: 3 | B8: 7.9125529e-64 | C8: 0.1631285 | D8: 1.9861702 | F8: 3 | G8: 2.2710678e-11 | H8: 25.737253 | I8: 31.154844 | K8: 3 | L8: 3.832858 | M8: 291.61521 | N8: 199.85785
A9: 4 | B9: 3.3799817e-64 | C9: 0.28518744 | D9: 1.9861702 | F9: 4 | G9: 4.4492775e-12 | H9: 24.716946 | I9: 41.127258 | K9: 4 | L9: 0.42444847 | M9: 402.13855 | N9: 186.86437
A10: 5 | B10: 2.6824025e-63 | C10: 4.3632833 | D10: 1.9861702 | F10: 5 | G10: 9.4598856e-11 | H10: 27.785682 | I10: 31.87247 | K10: 5 | L10: 0.30120568 | M10: 360.2747 | N10: 157.74663
A11: 6 | B11: 4.0354205e-64 | C11: 4.0201916 | D11: 1.9861702 | F11: 6 | G11: 9.4562078e-12 | H11: 25.73721 | I11: 49.685662 | K11: 6 | L11: 0.19930522 | M11: 327.37334 | N11: 137.85381
A12: 7 | B12: 5.4233878e-63 | C12: 0.053073682 | D12: 1.9861702 | F12: 7 | G12: 2.7028833e-12 | H12: 25.417989 | I12: 73.925175 | K12: 7 | L12: 0.14805565 | M12: 419.65446 | N12: 177.80149
A13: 8 | B13: 2.1254118e-63 | C13: 0.1368695 | D13: 4.8354314 | F13: 8 | G13: 5.3264896e-11 | H13: 25.037098 | I13: 34.721731 | K13: 8 | L13: 0.35710696 | M13: 418.33402 | N13: 149.0583
A14: 9 | B14: 1.982165e-61 | C14: 0.2309021 | D14: 4.8354314 | F14: 9 | G14: 3.9216795e-10 | H14: 25.444941 | I14: 41.137879 | K14: 9 | L14: 0.2729631 | M14: 253.1815 | N14: 166.4652
A15: 10 | B15: 1.192116e-61 | C15: 0.25590955 | D15: 3.4108008 | F15: 10 | G15: 8.9482838e-12 | H15: 28.370776 | I15: 38.995623 | K15: 10 | L15: 0.88441394 | M15: 320.51956 | N15: 117.05762
A16: 11 | B16: 7.3922676e-64 | C16: 0.29021156 | D16: 1.9861702 | F16: 11 | G16: 7.690642e-11 | H16: 79.295653 | I16: 56.10181 | K16: 11 | L16: 0.25675979 | M16: 378.80969 | N16: 190.49531
A17: 12 | B17: 1.2295627e-62 | C17: 4.0007961 | D17: 4.8354314 | F17: 12 | G17: 1.8654288e-12 | H17: 24.193337 | I17: 48.261032 | K17: 12 | L17: 0.24465986 | M17: 276.00082 | N17: 171.19619
... A55: 50 | B55: 2.3523813e-62 | C55: 0.33282966 | D55: 1.9861702 | F55: 50 | G55: 2.9510563e-13 | H55: 26.549968 | I55: 31.87247 | K55: 50 | L55: 0.21304575 | M55: 430.07263 | N55: 181.16368
A56: AVG | B56: =AVERAGE(B6:B55) -> 4.7161549e-61 | C56: =AVERAGE(C6:C55) -> 0.72572727 | D56: =AVERAGE(D6:D55) -> 2.8979339 | F56: AVG | G56: =AVERAGE(G6:G55) -> 2.8487904e-09 | H56: =AVERAGE(H6:H55) -> 33.00946 | I56: =AVERAGE(I6:I55) -> 40.833395 | K56: AVG | L56: =AVERAGE(L6:L55) -> 0.81224452 | M56: =AVERAGE(M6:M55) -> 464.22508 | N56: =AVERAGE(N6:N55) -> 163.18461
A57: MED | B57: =MEDIAN(B6:B55) -> 1.0742145e-62 | C57: =MEDIAN(C6:C55) -> 0.21569734 | D57: =MEDIAN(D6:D55) -> 3.4108008 | F57: MED | G57: =MEDIAN(G6:G55) -> 3.3489697e-11 | H57: =MEDIAN(H6:H55) -> 25.650196 | I57: =MEDIAN(I6:I55) -> 38.995398 | K57: MED | L57: =MEDIAN(L6:L55) -> 0.28323366 | M57: =MEDIAN(M6:M55) -> 371.92306 | N57: =MEDIAN(N6:N55) -> 165.52055
A58: VAR_S | B58: =_xlfn.VAR.S(B6:B55) -> 3.3625392e-120 | C58: =_xlfn.VAR.S(C6:C55) -> 1.8276017 | D58: =_xlfn.VAR.S(D6:D55) -> 0.9741949 | F58: VAR_S | G58: =_xlfn.VAR.S(G6:G55) -> 2.22744e-16 | H58: =_xlfn.VAR.S(H6:H55) -> 348.72146 | I58: =_xlfn.VAR.S(I6:I55) -> 173.7993 | K58: VAR_S | L58: =_xlfn.VAR.S(L6:L55) -> 5.1716958 | M58: =_xlfn.VAR.S(M6:M55) -> 249121.59 | N58: =_xlfn.VAR.S(N6:N55) -> 512.81241

Sheet FIPS
A1: W | B1: 0.6 | C1: 0.6 | D1: 0.6 | F1: W | G1: 0.6 | H1: 0.6 | I1: 0.6 | K1: W | L1: 0.6 | M1: 0.6 | N1: 0.6
A2: C | B2: 3 | C2: 3 | D2: 1.5 | F2: C | G2: 3 | H2: 3 | I2: 1.5 | K2: C | L2: 3 | M2: 3 | N2: 1.5
A3: K | B3: 10 | C3: 5 | D3: 2 | F3: K | G3: 10 | H3: 5 | I3: 2 | K3: K | L3: 10 | M3: 5 | N3: 2
A4: FIPS | C4: D = 5 | F4: FIPS | H4: D = 30 | K4: FIPS | M4: D = 100
A5: Trial | B5: Sphere | C5: Rosenbrock | D5: Rastrigin | F5: Trial | G5: Sphere | H5: Rosenbrock | I5: Rastrigin | K5: Trial | L5: Sphere | M5: Rosenbrock | N5: Rastrigin
A6: 1 | B6: 1.3822589e-39 | C6: 2.1589997 | D6: 3.4108008 | F6: 1 | G6: 5.5054432e-18 | H6: 27.905892 | I6: 17.615544 | K6: 1 | L6: 0.28113555 | M6: 132.03764 | N6: 53.98622
A7: 2 | B7: 6.2261833e-39 | C7: 3.0153314 | D7: 1.9861702 | F7: 2 | G7: 2.1561328e-11 | H7: 28.661077 | I7: 14.766283 | K7: 2 | L7: 0.38027076 | M7: 139.3105 | N7: 61.119686
A8: 3 | B8: 9.6275405e-39 | C8: 2.2706162 | D8: 1.9861702 | F8: 3 | G8: 4.4257535e-13 | H8: 28.9085 | I8: 16.190913 | K8: 3 | L8: 0.31644421 | M8: 117.37907 | N8: 68.258217
A9: 4 | B9: 1.490148e-39 | C9: 2.5487481 | D9: 1.9861702 | F9: 4 | G9: 1.3039631e-12 | H9: 28.374766 | I9: 17.615544 | K9: 4 | L9: 0.27277043 | M9: 129.01676 | N9: 59.685315
A10: 5 | B10: 3.0739971e-39 | C10: 2.7650776 | D10: 1.9861702 | F10: 5 | G10: 1.8965809e-09 | H10: 28.59916 | I10: 13.341652 | K10: 5 | L10: 0.17541742 | M10: 130.52791 | N10: 62.545039
A11: 6 | B11: 9.7956961e-39 | C11: 2.1825696 | D11: 1.9861702 | F11: 6 | G11: 5.6529682e-30 | H11: 28.454903 | I11: 17.615544 | K11: 6 | L11: 0.20948543 | M11: 143.47952 | N11: 63.961013
A12: 7 | B12: 2.2364669e-39 | C12: 2.6548384 | D12: 1.9861702 | F12: 7 | G12: 3.0742023e-09 | H12: 28.47725 | I12: 13.341652 | K12: 7 | L12: 0.28992989 | M12: 149.92386 | N12: 62.538525
A13: 8 | B13: 8.0399495e-40 | C13: 2.307953 | D13: 4.8354314 | F13: 8 | G13: 3.9855428e-08 | H13: 28.422409 | I13: 13.341652 | K13: 8 | L13: 0.33467097 | M13: 137.80765 | N13: 51.140887
A14: 9 | B14: 1.2777191e-38 | C14: 2.727441 | D14: 1.9861702 | F14: 9 | G14: 1.074857e-24 | H14: 28.371347 | I14: 14.766283 | K14: 9 | L14: 0.31475205 | M14: 134.49793 | N14: 61.108525
A15: 10 | B15: 4.793823e-39 | C15: 2.3243398 | D15: 1.9861702 | F15: 10 | G15: 4.3385733e-12 | H15: 27.564741 | I15: 13.341652 | K15: 10 | L15: 0.1974509 | M15: 150.79669 | N15: 53.992491
A16: 11 | B16: 2.2793589e-39 | C16: 2.5119588 | D16: 1.9861702 | F16: 11 | G16: 8.7233324e-20 | H16: 29.149128 | I16: 14.766283 | K16: 11 | L16: 0.22892066 | M16: 144.24131 | N16: 53.987269
A17: 12 | B17: 3.3776769e-39 | C17: 2.8491714 | D17: 1.9861702 | F17: 12 | G17: 2.1664187e-10 | H17: 28.2508 | I17: 20.464805 | K17: 12 | L17: 0.26555339 | M17: 116.90918 | N17: 52.564941
... A55: 50 | B55: 1.3534819e-38 | C55: 2.6666599 | D55: 3.4108008 | F55: 50 | G55: 2.2391976e-13 | H55: 28.636221 | I55: 16.190913 | K55: 50 | L55: 0.39168954 | M55: 133.15487 | N55: 52.566089
A56: AVG | B56: =AVERAGE(B6:B55) -> 5.4595193e-39 | C56: =AVERAGE(C6:C55) -> 2.5563755 | D56: =AVERAGE(D6:D55) -> 2.3546294 | F56: AVG | G56: =AVERAGE(G6:G55) -> 2.0982724e-06 | H56: =AVERAGE(H6:H55) -> 28.394975 | I56: =AVERAGE(I6:I55) -> 16.133928 | K56: AVG | L56: =AVERAGE(L6:L55) -> 0.28320497 | M56: =AVERAGE(M6:M55) -> 131.75683 | N56: =AVERAGE(N6:N55) -> 59.320708
A57: MED | B57: =MEDIAN(B6:B55) -> 4.4801773e-39 | C57: =MEDIAN(C6:C55) -> 2.634016 | D57: =MEDIAN(D6:D55) -> 1.9861702 | F57: MED | G57: =MEDIAN(G6:G55) -> 3.3324756e-13 | H57: =MEDIAN(H6:H55) -> 28.438656 | I57: =MEDIAN(I6:I55) -> 16.190913 | K57: MED | L57: =MEDIAN(L6:L55) -> 0.27869535 | M57: =MEDIAN(M6:M55) -> 131.28277 | N57: =MEDIAN(N6:N55) -> 59.686565
A58: VAR_S | B58: =_xlfn.VAR.S(B6:B55) -> 1.3157213e-77 | C58: =_xlfn.VAR.S(C6:C55) -> 0.082526705 | D58: =_xlfn.VAR.S(D6:D55) -> 0.56014333 | F58: VAR_S | G58: =_xlfn.VAR.S(G6:G55) -> 2.1096432e-10 | H58: =_xlfn.VAR.S(H6:H55) -> 0.11182011 | I58: =_xlfn.VAR.S(I6:I55) -> 5.2984272 | K58: VAR_S | L58: =_xlfn.VAR.S(L6:L55) -> 0.0052481507 | M58: =_xlfn.VAR.S(M6:M55) -> 98.603645 | N58: =_xlfn.VAR.S(N6:N55) -> 31.74914

Sheet Hybrid_PSO
A1: W | B1: 0.3 | C1: 0.3 | D1: 0.3 | F1: W | G1: 0.3 | H1: 0.3 | I1: 0.3 | K1: W | L1: 0.3 | M1: 0.3 | N1: 0.3
A2: C1 | B2: 2 | C2: 2 | D2: 1.5 | F2: C1 | G2: 2 | H2: 2 | I2: 1.5 | K2: C1 | L2: 2 | M2: 2 | N2: 1.5
A3: C2 | B3: 2 | C3: 2 | D3: 2 | F3: C2 | G3: 2 | H3: 2 | I3: 2 | K3: C2 | L3: 2 | M3: 2 | N3: 2
A4: MR | B4: 0.11 | C4: 0.2 | D4: 0.2 | F4: MR | G4: 0.11 | H4: 0.2 | I4: 0.2 | K4: MR | L4: 0.11 | M4: 0.2 | N4: 0.2
A5: Hybrid PSO | C5: D = 5 | F5: Hybrid PSO | H5: D = 30 | K5: Hybrid PSO | M5: D = 100
A6: Trial | B6: Sphere | C6: Rosenbrock | D6: Rastrigin | F6: Trial | G6: Sphere | H6: Rosenbrock | I6: Rastrigin | K6: Trial | L6: Sphere | M6: Rosenbrock | N6: Rastrigin
A7: 1 | B7: 6.4260167e-62 | C7: 0.2786353 | D7: 1.9861702 | F7: 1 | G7: 1.1653298e-06 | H7: 24.834385 | I7: 39.05444 | K7: 1 | L7: 0.39553152 | M7: 419.97523 | N7: 214.62396
A8: 2 | B8: 1.9173744e-61 | C8: 3.9323658 | D8: 4.8354314 | F8: 2 | G8: 2.7504654e-11 | H8: 81.966706 | I8: 51.124172 | K8: 2 | L8: 0.87201422 | M8: 529.65624 | N8: 231.87027
A9: 3 | B9: 4.4723292e-63 | C9: 0.2842026 | D9: 3.4108008 | F9: 3 | G9: 1.3261305e-11 | H9: 24.404175 | I9: 32.589944 | K9: 3 | L9: 3.5663568 | M9: 449.08098 | N9: 225.11631
A10: 4 | B10: 3.5936394e-62 | C10: 0.17434935 | D10: 1.9861702 | F10: 4 | G10: 1.9001945e-11 | H10: 24.320991 | I10: 41.178816 | K10: 4 | L10: 0.18411696 | M10: 219.43599 | N10: 162.63731
A11: 5 | B11: 5.9121201e-63 | C11: 0.25953099 | D11: 1.9861702 | F11: 5 | G11: 4.3206068e-11 | H11: 25.360941 | I11: 32.601687 | K11: 5 | L11: 5.6496249 | M11: 320.99165 | N11: 209.917
A12: 6 | B12: 2.3102779e-64 | C12: 0.35519607 | D12: 1.9861702 | F12: 6 | G12: 1.142023e-10 | H12: 23.394486 | I12: 32.580323 | K12: 6 | L12: 0.27173272 | M12: 348.01806 | N12: 302.08049
A13: 7 | B13: 7.1695859e-63 | C13: 0.20330311 | D13: 1.9861702 | F13: 7 | G13: 2.3834868e-11 | H13: 20.758975 | I13: 34.443903 | K13: 7 | L13: 0.16292475 | M13: 201.71899 | N13: 322.30546
A14: 8 | B14: 5.7690318e-63 | C14: 0.26732894 | D14: 1.9861702 | F14: 8 | G14: 1.8653979e-10 | H14: 25.369262 | I14: 35.524212 | K14: 8 | L14: 4.4469391 | M14: 454.25524 | N14: 328.03424
A15: 9 | B15: 7.517704e-62 | C15: 0.015306696 | D15: 4.8354314 | F15: 9 | G15: 6.864116e-11 | H15: 24.725616 | I15: 29.731522 | K15: 9 | L15: 0.10221812 | M15: 181.94767 | N15: 230.97643
A16: 10 | B16: 8.67178e-61 | C16: 0.28889278 | D16: 3.4108008 | F16: 10 | G16: 2.560224e-10 | H16: 25.570982 | I16: 46.841332 | K16: 10 | L16: 0.3691665 | M16: 350.30209 | N16: 317.36713
A17: 11 | B17: 3.2128053e-62 | C17: 0.2967103 | D17: 6.260062 | F17: 11 | G17: 4.042329e-11 | H17: 82.089431 | I17: 56.187031 | K17: 11 | L17: 0.11995165 | M17: 327.21703 | N17: 267.18106
A18: 12 | B18: 1.2977638e-62 | C18: 0.06650088 | D18: 3.4108008 | F18: 12 | G18: 8.1075998e-06 | H18: 29.225948 | I18: 32.309082 | K18: 12 | L18: 0.18997443 | M18: 202.15678 | N18: 189.61443
... A56: 50 | B56: 1.7181828e-61 | C56: 0.35204039 | D56: 1.9861702 | F56: 50 | G56: 1.5721222e-11 | H56: 81.264811 | I56: 31.237268 | K56: 50 | L56: 13.771542 | M56: 336.02845 | N56: 298.64786
A57: AVG | B57: =AVERAGE(B7:B56) -> 4.1558946e-61 | C57: =AVERAGE(C7:C56) -> 0.82037959 | D57: =AVERAGE(D7:D56) -> 3.8951752 | F57: AVG | G57: =AVERAGE(G7:G56) -> 1.9371123e-07 | H57: =AVERAGE(H7:H56) -> 32.390919 | I57: =AVERAGE(I7:I56) -> 39.753333 | K57: AVG | L57: =AVERAGE(L7:L56) -> 1.0292377 | M57: =AVERAGE(M7:M56) -> 373.5987 | N57: =AVERAGE(N7:N56) -> 258.505
A58: MED | B58: =MEDIAN(B7:B56) -> 3.4150576e-62 | C58: =MEDIAN(C7:C56) -> 0.26342996 | D58: =MEDIAN(D7:D56) -> 3.4108008 | F58: MED | G58: =MEDIAN(G7:G56) -> 4.3306516e-11 | H58: =MEDIAN(H7:H56) -> 25.437643 | I58: =MEDIAN(I7:I56) -> 38.473004 | K58: MED | L58: =MEDIAN(L7:L56) -> 0.23531347 | M58: =MEDIAN(M7:M56) -> 357.45755 | N58: =MEDIAN(N7:N56) -> 263.31276
A59: VAR_S | B59: =_xlfn.VAR.S(B7:B56) -> 1.5955849e-120 | C59: =_xlfn.VAR.S(C7:C56) -> 2.024766 | D59: =_xlfn.VAR.S(D7:D56) -> 2.2043641 | F59: VAR_S | G59: =_xlfn.VAR.S(G7:G56) -> 1.3343232e-12 | H59: =_xlfn.VAR.S(H7:H56) -> 373.62885 | I59: =_xlfn.VAR.S(I7:I56) -> 103.49626 | K59: VAR_S | L59: =_xlfn.VAR.S(L7:L56) -> 5.9835742 | M59: =_xlfn.VAR.S(M7:M56) -> 12063.02 | N59: =_xlfn.VAR.S(N7:N56) -> 1394.5014

Sheet GA-Boids
A1: W | B1: 0.3 | C1: 0.3 | D1: 0.3 | F1: W | G1: 0.3 | H1: 0.3 | I1: 0.3 | K1: W | L1: 0.3 | M1: 0.3 | N1: 0.3
A2: ALIGNMENT WEIGHT | B2: 0.3 | C2: 0.5 | D2: 0.3 | F2: ALIGNMENT WEIGHT | G2: 0.3 | H2: 0.5 | I2: 0.3 | K2: ALIGNMENT WEIGHT | L2: 0.3 | M2: 0.5 | N2: 0.3
A3: COHESION WEIGHT | B3: 0.3 | C3: 0.5 | D3: 0.3 | F3: COHESION WEIGHT | G3: 0.3 | H3: 0.5 | I3: 0.3 | K3: COHESION WEIGHT | L3: 0.3 | M3: 0.5 | N3: 0.3
A4: SEPARATION WEIGHT | B4: 0.3 | C4: 0.8 | D4: 0.3 | F4: SEPARATION WEIGHT | G4: 0.3 | H4: 0.8 | I4: 0.3 | K4: SEPARATION WEIGHT | L4: 0.3 | M4: 0.8 | N4: 0.3
A5: GLOBAL BEST ATTRACTION | B5: 0.8 | C5: 0.8 | D5: 0.8 | F5: GLOBAL BEST ATTRACTION | G5: 0.8 | H5: 0.8 | I5: 0.8 | K5: GLOBAL BEST ATTRACTION | L5: 0.8 | M5: 0.8 | N5: 0.8
A6: NEIGHBOR RADIUS | B6: 0.2 | C6: 0.2 | D6: 0.2 | F6: NEIGHBOR RADIUS | G6: 0.2 | H6: 0.2 | I6: 0.2 | K6: NEIGHBOR RADIUS | L6: 0.2 | M6: 0.2 | N6: 0.2
A7: CROSSOVER RATE | B7: 0.9 | C7: 0.9 | D7: 0.9 | F7: CROSSOVER RATE | G7: 0.9 | H7: 0.9 | I7: 0.9 | K7: CROSSOVER RATE | L7: 0.9 | M7: 0.9 | N7: 0.9
A8: MUTATION RATE | B8: 0.02 | C8: 0.02 | D8: 0.11 | F8: MUTATION RATE | G8: 0.02 | H8: 0.02 | I8: 0.11 | K8: MUTATION RATE | L8: 0.02 | M8: 0.02 | N8: 0.11
A9: ELITE COUNT | B9: 5 | C9: 5 | D9: 2 | F9: ELITE COUNT | G9: 5 | H9: 5 | I9: 2 | K9: ELITE COUNT | L9: 5 | M9: 5 | N9: 2
A10: GA-BOIDS | C10: D = 5 | F10: GA-BOIDS | H10: D = 30 | K10: GA-BOIDS | M10: D = 100
A11: Trial | B11: Sphere | C11: Rosenbrock | D11: Rastrigin | F11: Trial | G11: Sphere | H11: Rosenbrock | I11: Rastrigin | K11: Trial | L11: Sphere | M11: Rosenbrock | N11: Rastrigin
A12: 1 | B12: 0.00093055307 | C12: 0.76068784 | D12: 3.4368336 | F12: 1 | G12: 0.0024575628 | H12: 28.158672 | I12: 33.122061 | K12: 1 | L12: 0.11914818 | M12: 180.26316 | N12: 249.06224
A13: 2 | B13: 0.0014112723 | C13: 0.35140734 | D13: 3.4415761 | F13: 2 | G13: 0.0028433895 | H13: 27.999981 | I13: 27.198361 | K13: 2 | L13: 0.11930701 | M13: 423.66261 | N13: 213.77522
A14: 3 | B14: 0.00055552092 | C14: 0.24286664 | D14: 3.4540668 | F14: 3 | G14: 0.001610913 | H14: 27.905542 | I14: 36.604904 | K14: 3 | L14: 0.1416134 | M14: 290.09013 | N14: 242.84223
A15: 4 | B15: 0.0013730161 | C15: 0.94362959 | D15: 4.860506 | F15: 4 | G15: 0.0028040066 | H15: 28.011568 | I15: 39.392893 | K15: 4 | L15: 0.11519802 | M15: 184.52919 | N15: 231.30832
A16: 5 | B16: 0.0005635892 | C16: 0.81579472 | D16: 3.4640437 | F16: 5 | G16: 0.0017600368 | H16: 22.340099 | I16: 34.837266 | K16: 5 | L16: 0.11191287 | M16: 246.99743 | N16: 222.26169
A17: 6 | B17: 0.00073776281 | C17: 0.24672929 | D17: 2.022628 | F17: 6 | G17: 0.0025580978 | H17: 24.104739 | I17: 47.046353 | K17: 6 | L17: 0.12173112 | M17: 228.51598 | N17: 242.60323
A18: 7 | B18: 0.0016920076 | C18: 0.57305439 | D18: 4.9378564 | F18: 7 | G18: 0.0025326048 | H18: 26.018159 | I18: 46.881907 | K18: 7 | L18: 0.14586531 | M18: 233.28096 | N18: 263.59379
A19: 8 | B19: 0.00048298399 | C19: 1.9755847 | D19: 3.4431197 | F19: 8 | G19: 0.0027598276 | H19: 28.204694 | I19: 37.326014 | K19: 8 | L19: 0.097894973 | M19: 117.99618 | N19: 305.29326
A20: 9 | B20: 0.00097349428 | C20: 0.53664997 | D20: 4.8689969 | F20: 9 | G20: 0.0033521954 | H20: 27.862368 | I20: 21.856867 | K20: 9 | L20: 0.12530557 | M20: 181.2488 | N20: 192.79069
A21: 10 | B21: 0.00060642199 | C21: 0.38099831 | D21: 4.8847989 | F21: 10 | G21: 0.0030955491 | H21: 29.389813 | I21: 57.589521 | K21: 10 | L21: 0.14234513 | M21: 312.59935 | N21: 246.21519
A22: 11 | B22: 0.0011243197 | C22: 1.3705817 | D22: 6.2898796 | F22: 11 | G22: 0.0026658914 | H22: 28.076436 | I22: 56.181333 | K22: 11 | L22: 0.1409061 | M22: 370.83167 | N22: 219.74985
A23: 12 | B23: 0.000672805 | C23: 0.84171912 | D23: 6.3241245 | F23: 12 | G23: 0.0033697709 | H23: 29.440734 | I23: 44.83976 | K23: 12 | L23: 0.10990254 | M23: 328.78497 | N23: 259.99462
... A61: 50 | B61: 0.0013684695 | C61: 0.82211042 | D61: 4.9235602 | F61: 50 | G61: 0.0022839182 | H61: 27.784765 | I61: 34.266429 | K61: 50 | L61: 0.13054158 | M61: 249.28198 | N61: 234.68105
A62: AVG | B62: =AVERAGE(B12:B61) -> 0.00099791606 | C62: =AVERAGE(C12:C61) -> 1.397391 | D62: =AVERAGE(D12:D61) -> 4.3659867 | F62: AVG | G62: =AVERAGE(G12:G61) -> 0.0027545318 | H62: =AVERAGE(H12:H61) -> 38.281828 | I62: =AVERAGE(I12:I61) -> 40.404773 | K62: AVG | L62: =AVERAGE(L12:L61) -> 0.12073023 | M62: =AVERAGE(M12:M61) -> 256.7517 | N62: =AVERAGE(N12:N61) -> 239.96537
A63: MED | B63: =MEDIAN(B12:B61) -> 0.00097193059 | C63: =MEDIAN(C12:C61) -> 0.77841963 | D63: =MEDIAN(D12:D61) -> 4.8564121 | F63: MED | G63: =MEDIAN(G12:G61) -> 0.0026902314 | H63: =MEDIAN(H12:H61) -> 28.181683 | I63: =MEDIAN(I12:I61) -> 39.985368 | K63: MED | L63: =MEDIAN(L12:L61) -> 0.11974703 | M63: =MEDIAN(M12:M61) -> 248.74093 | N63: =MEDIAN(N12:N61) -> 235.84579
A64: VAR_S | B64: =_xlfn.VAR.S(B12:B61) -> 2.2079817e-07 | C64: =_xlfn.VAR.S(C12:C61) -> 2.2127516 | D64: =_xlfn.VAR.S(D12:D61) -> 3.0075651 | F64: VAR_S | G64: =_xlfn.VAR.S(G12:G61) -> 3.169672e-07 | H64: =_xlfn.VAR.S(H12:H61) -> 463.9754 | I64: =_xlfn.VAR.S(I12:I61) -> 81.127061 | K64: VAR_S | L64: =_xlfn.VAR.S(L12:L61) -> 0.00027895664 | M64: =_xlfn.VAR.S(M12:M61) -> 4669.679 | N64: =_xlfn.VAR.S(N12:N61) -> 989.34106

Sheet Results
A1: Medians | F1: Means | K1: Variances
A2: D=5 | F2: D=5 | K2: D=5
A3: Algorithm | B3: Sphere | C3: Rosenbrock | D3: Rastrigin | F3: Algorithm | G3: Sphere | H3: Rosenbrock | I3: Rastrigin | K3: Algorithm | L3: Sphere | M3: Rosenbrock | N3: Rastrigin
A4: GA | B4: =GA!B57 -> 1.2000283e-28 | C4: =GA!C57 -> 0.33267242 | D4: =GA!D57 -> 1.9861702 | F4: GA | G4: =GA!B56 -> 3.038014e-25 | H4: =GA!C56 -> 0.48835396 | I4: =GA!D56 -> 2.3850667 | K4: GA | L4: =GA!B58 -> 3.1989718e-48 | M4: =GA!C58 -> 0.23731538 | N4: =GA!D58 -> 0.66603109
A5: PSO | B5: =PSO!B57 -> 1.0742145e-62 | C5: =PSO!C57 -> 0.21569734 | D5: =PSO!D57 -> 3.4108008 | F5: PSO | G5: =PSO!B56 -> 4.7161549e-61 | H5: =PSO!C56 -> 0.72572727 | I5: =PSO!D56 -> 2.8979339 | K5: PSO | L5: =PSO!B58 -> 3.3625392e-120 | M5: =PSO!C58 -> 1.8276017 | N5: =PSO!D58 -> 0.9741949
A6: FIPS | B6: =FIPS!B57 -> 4.4801773e-39 | C6: =FIPS!C57 -> 2.634016 | D6: =FIPS!D57 -> 1.9861702 | F6: FIPS | G6: =FIPS!B56 -> 5.4595193e-39 | H6: =FIPS!C56 -> 2.5563755 | I6: =FIPS!D56 -> 2.3546294 | K6: FIPS | L6: =FIPS!B58 -> 1.3157213e-77 | M6: =FIPS!C58 -> 0.082526705 | N6: =FIPS!D58 -> 0.56014333
A7: Hybrid PSO | B7: =Hybrid_PSO!B58 -> 3.4150576e-62 | C7: =Hybrid_PSO!C58 -> 0.26342996 | D7: =Hybrid_PSO!D58 -> 3.4108008 | F7: Hybrid PSO | G7: =Hybrid_PSO!B57 -> 4.1558946e-61 | H7: =Hybrid_PSO!C57 -> 0.82037959 | I7: =Hybrid_PSO!D57 -> 3.8951752 | K7: Hybrid PSO | L7: =Hybrid_PSO!B59 -> 1.5955849e-120 | M7: =Hybrid_PSO!C59 -> 2.024766 | N7: =Hybrid_PSO!D59 -> 2.2043641
A8: GA Boids | B8: ='GA-Boids'!B63 -> 0.00097193059 | C8: ='GA-Boids'!C63 -> 0.77841963 | D8: ='GA-Boids'!D63 -> 4.8564121 | F8: GA Boids | G8: ='GA-Boids'!B62 -> 0.00099791606 | H8: ='GA-Boids'!C62 -> 1.397391 | I8: ='GA-Boids'!D62 -> 4.3659867 | K8: GA Boids | L8: ='GA-Boids'!B64 -> 2.2079817e-07 | M8: ='GA-Boids'!C64 -> 2.2127516 | N8: ='GA-Boids'!D64 -> 3.0075651
A12: D=30 | F12: D=30 | K12: D=30
A13: Algorithm | B13: Sphere | C13: Rosenbrock | D13: Rastrigin | F13: Algorithm | G13: Sphere | H13: Rosenbrock | I13: Rastrigin | K13: Algorithm | L13: Sphere | M13: Rosenbrock | N13: Rastrigin
A14: GA | B14: =GA!G57 -> 0.00065182041 | C14: =GA!H57 -> 109.32052 | D14: =GA!I57 -> 22.638741 | F14: GA | G14: =GA!G56 -> 0.55429475 | H14: =GA!H56 -> 648.96258 | I14: =GA!I56 -> 25.820841 | K14: GA | L14: =GA!G58 -> 2.75522 | M14: =GA!H58 -> 10446324 | N14: =GA!I58 -> 69.437994
A15: PSO | B15: =PSO!G57 -> 3.3489697e-11 | C15: =PSO!H57 -> 25.650196 | D15: =PSO!I57 -> 38.995398 | F15: PSO | G15: =PSO!G56 -> 2.8487904e-09 | H15: =PSO!H56 -> 33.00946 | I15: =PSO!I56 -> 40.833395 | K15: PSO | L15: =PSO!G58 -> 2.22744e-16 | M15: =PSO!H58 -> 348.72146 | N15: =PSO!I58 -> 173.7993
A16: FIPS | B16: =FIPS!G57 -> 3.3324756e-13 | C16: =FIPS!H57 -> 28.438656 | D16: =FIPS!I57 -> 16.190913 | F16: FIPS | G16: =FIPS!G56 -> 2.0982724e-06 | H16: =FIPS!H56 -> 28.394975 | I16: =FIPS!I56 -> 16.133928 | K16: FIPS | L16: =FIPS!G58 -> 2.1096432e-10 | M16: =FIPS!H58 -> 0.11182011 | N16: =FIPS!I58 -> 5.2984272
A17: Hybrid PSO | B17: =Hybrid_PSO!G58 -> 4.3306516e-11 | C17: =Hybrid_PSO!H58 -> 25.437643 | D17: =Hybrid_PSO!I58 -> 38.473004 | F17: Hybrid PSO | G17: =Hybrid_PSO!G57 -> 1.9371123e-07 | H17: =Hybrid_PSO!H57 -> 32.390919 | I17: =Hybrid_PSO!I57 -> 39.753333 | K17: Hybrid PSO | L17: =Hybrid_PSO!G59 -> 1.3343232e-12 | M17: =Hybrid_PSO!H59 -> 373.62885 | N17: =Hybrid_PSO!I59 -> 103.49626
A18: GA Boids | B18: ='GA-Boids'!G63 -> 0.0026902314 | C18: ='GA-Boids'!H63 -> 28.181683 | D18: ='GA-Boids'!I63 -> 39.985368 | F18: GA Boids | G18: ='GA-Boids'!G62 -> 0.0027545318 | H18: ='GA-Boids'!H62 -> 38.281828 | I18: ='GA-Boids'!I62 -> 40.404773 | K18: GA Boids | L18: ='GA-Boids'!G64 -> 3.169672e-07 | M18: ='GA-Boids'!H64 -> 463.9754 | N18: ='GA-Boids'!I64 -> 81.127061
A22: D=100 | F22: D=100 | K22: D=100
A23: Algorithm | B23: Sphere | C23: Rosenbrock | D23: Rastrigin | F23: Algorithm | G23: Sphere | H23: Rosenbrock | I23: Rastrigin | K23: Algorithm | L23: Sphere | M23: Rosenbrock | N23: Rastrigin
A24: GA | B24: =GA!L57 -> 112.02579 | C24: =PSO!M57 -> 371.92306 | D24: =GA!N57 -> 512.15859 | F24: GA | G24: =GA!L56 -> 115.15322 | H24: =GA!M56 -> 90177.62 | I24: =GA!N56 -> 524.19524 | K24: GA | L24: =GA!L58 -> 1949.7272 | M24: =GA!M58 -> 1.9613105e+09 | N24: =GA!N58 -> 6629.6156
A25: PSO | B25: =PSO!L57 -> 0.28323366 | C25: =PSO!M57 -> 371.92306 | D25: =PSO!N57 -> 165.52055 | F25: PSO | G25: =PSO!L56 -> 0.81224452 | H25: =PSO!M56 -> 464.22508 | I25: =PSO!N56 -> 163.18461 | K25: PSO | L25: =PSO!L58 -> 5.1716958 | M25: =PSO!M58 -> 249121.59 | N25: =PSO!N58 -> 512.81241
A26: FIPS | B26: =FIPS!L57 -> 0.27869535 | C26: =FIPS!M57 -> 131.28277 | D26: =FIPS!N57 -> 59.686565 | F26: FIPS | G26: =FIPS!L56 -> 0.28320497 | H26: =FIPS!M56 -> 131.75683 | I26: =FIPS!N56 -> 59.320708 | K26: FIPS | L26: =FIPS!L58 -> 0.0052481507 | M26: =FIPS!M58 -> 98.603645 | N26: =FIPS!N58 -> 31.74914
A27: Hybrid PSO | B27: =Hybrid_PSO!L58 -> 0.23531347 | C27: =Hybrid_PSO!M58 -> 357.45755 | D27: =Hybrid_PSO!N58 -> 263.31276 | F27: Hybrid PSO | G27: =Hybrid_PSO!L57 -> 1.0292377 | H27: =Hybrid_PSO!M57 -> 373.5987 | I27: =Hybrid_PSO!N57 -> 258.505 | K27: Hybrid PSO | L27: =Hybrid_PSO!L59 -> 5.9835742 | M27: =Hybrid_PSO!M59 -> 12063.02 | N27: =Hybrid_PSO!N59 -> 1394.5014
A28: GA Boids | B28: ='GA-Boids'!L63 -> 0.11974703 | C28: ='GA-Boids'!M63 -> 248.74093 | D28: ='GA-Boids'!N63 -> 235.84579 | F28: GA Boids | G28: ='GA-Boids'!L62 -> 0.12073023 | H28: ='GA-Boids'!M62 -> 256.7517 | I28: ='GA-Boids'!N62 -> 239.96537 | K28: GA Boids | L28: ='GA-Boids'!L64 -> 0.00027895664 | M28: ='GA-Boids'!M64 -> 4669.679 | N28: ='GA-Boids'!N64 -> 989.34106
A31: t-test comparing GA-Boids with other algorithms | G31: df | M31: different
A32: t | B32: Algorithm | C32: D=5 | D32: D=30 | E32: D=100 | G32: df | H32: Algorithm | I32: D=5 | J32: D=30 | K32: D=100 | M32: 2-sided p | N32: Algorithm | O32: D=5 | P32: D=30 | Q32: D=100 | S32: Statistically different | T32: Algorithm | U32: D=5 | V32: D=30 | W32: D=100
A33: Sphere | B33: GA | C33: =($G$8-G4)/(SQRT(($L$8/50)+(L4/50))) -> 15.016934 | D33: =($G$18-G14)/(SQRT(($L$18/50)+(L14/50))) -> -2.3495464 | E33: =($G$28-G24)/(SQRT(($L$28/50)+(L24/50))) -> -18.421227 | G33: Sphere | H33: GA | I33: =49*(($L$8+L4)^2)/($L$8^2+L4^2) -> 49 | J33: =49*(($L$18+L14)^2)/($L$18^2+L14^2) -> 49.000011 | K33: =49*(($L$28+L24)^2)/($L$28^2+L24^2) -> 49.000014 | M33: Sphere | N33: GA | O33: 0 | P33: 0.0228 | Q33: 0 | S33: Sphere | T33: GA | U33: =IF(O33>=0.05, FALSE, TRUE) -> TRUE | V33: =IF(P33>=0.05, FALSE, TRUE) -> TRUE | W33: =IF(Q33>=0.05, FALSE, TRUE) -> TRUE
B34: PSO | C34: =($G$8-G5)/(SQRT(($L$8/50)+(L5/50))) -> 15.016934 | D34: =($G$18-G15)/(SQRT(($L$18/50)+(L15/50))) -> 34.595943 | E34: =($G$28-G25)/(SQRT(($L$28/50)+(L25/50))) -> -2.1500965 | H34: PSO | I34: =49*(($L$8+L5)^2)/($L$8^2+L5^2) -> 49 | J34: =49*(($L$18+L15)^2)/($L$18^2+L15^2) -> 49 | K34: =49*(($L$28+L25)^2)/($L$28^2+L25^2) -> 49.005286 | N34: PSO | O34: 0 | P34: 0 | Q34: 0.036 | T34: PSO | U34: =IF(O34>=0.05, FALSE, TRUE) -> TRUE | V34: =IF(P34>=0.05, FALSE, TRUE) -> TRUE | W34: =IF(Q34>=0.05, FALSE, TRUE) -> TRUE
B35: FIPS | C35: =($G$8-G6)/(SQRT(($L$8/50)+(L6/50))) -> 15.016934 | D35: =($G$18-G16)/(SQRT(($L$18/50)+(L16/50))) -> 34.558127 | E35: =($G$28-G26)/(SQRT(($L$28/50)+(L26/50))) -> -15.453324 | H35: FIPS | I35: =49*(($L$8+L6)^2)/($L$8^2+L6^2) -> 49 | J35: =49*(($L$18+L16)^2)/($L$18^2+L16^2) -> 49.065226 | K35: =49*(($L$28+L26)^2)/($L$28^2+L26^2) -> 54.19435 | N35: FIPS | O35: 0 | P35: 0 | Q35: 0 | T35: FIPS | U35: =IF(O35>=0.05, FALSE, TRUE) -> TRUE | V35: =IF(P35>=0.05, FALSE, TRUE) -> TRUE | W35: =IF(Q35>=0.05, FALSE, TRUE) -> TRUE
B36: Hybrid PSO | C36: =($G$8-G7)/(SQRT(($L$8/50)+(L7/50))) -> 15.016934 | D36: =($G$18-G17)/(SQRT(($L$18/50)+(L17/50))) -> 34.593474 | E36: =($G$28-G27)/(SQRT(($L$28/50)+(L27/50))) -> -2.6261713 | H36: Hybrid PSO | I36: =49*(($L$8+L7)^2)/($L$8^2+L7^2) -> 49 | J36: =49*(($L$18+L17)^2)/($L$18^2+L17^2) -> 49.000413 | K36: =49*(($L$28+L27)^2)/($L$28^2+L27^2) -> 49.004569 | N36: Hybrid PSO | O36: 0 | P36: 0 | Q36: 0.011 | T36: Hybrid PSO | U36: =IF(O36>=0.05, FALSE, TRUE) -> TRUE | V36: =IF(P36>=0.05, FALSE, TRUE) -> TRUE | W36: =IF(Q36>=0.05, FALSE, TRUE) -> TRUE
A37: Rosenbrock | B37: GA | C37: =($H$8-H4)/(SQRT(($M$8/50)+(M4/50))) -> 4.1065548 | D37: =($H$18-H14)/(SQRT(($M$18/50)+(M14/50))) -> -1.3360043 | E37: =($H$28-H24)/(SQRT(($M$28/50)+(M24/50))) -> -14.357268 | G37: Rosenbrock | H37: GA | I37: =49*(($M$8+M4)^2)/($M$8^2+M4^2) -> 59.390882 | J37: =49*(($M$18+M14^2)/($M$18^2+M14^2)) -> 49 | K37: =49*(($M$28+M24)^2)/($M$28^2+M24^2) -> 49.000233 | M37: Rosenbrock | N37: GA | O37: 0 | P37: 0.186 | Q37: 0 | S37: Rosenbrock | T37: GA | U37: =IF(O37>=0.05, FALSE, TRUE) -> TRUE | V37: =IF(P37>=0.05, FALSE, TRUE) -> FALSE | W37: =IF(Q37>=0.05, FALSE, TRUE) -> TRUE
B38: PSO | C38: =($H$8-H5)/(SQRT(($M$8/50)+(M5/50))) -> 2.3628016 | D38: =($H$18-H15)/(SQRT(($M$18/50)+(M15/50))) -> 1.3077552 | E38: =($H$28-H25)/(SQRT(($M$28/50)+(M25/50))) -> -2.9121185 | H38: PSO | I38: =49*(($M$8+M5)^2)/($M$8^2+M5^2) -> 97.117493 | J38: =49*(($M$18+M15^2)/($M$18^2+M15^2)) -> 17.755474 | K38: =49*(($M$28+M25)^2)/($M$28^2+M25^2) -> 50.836323 | N38: PSO | O38: 0.02 | P38: 0.2068 | Q38: 0.005 | T38: PSO | U38: =IF(O38>=0.05, FALSE, TRUE) -> TRUE | V38: =IF(P38>=0.05, FALSE, TRUE) -> FALSE | W38: =IF(Q38>=0.05, FALSE, TRUE) -> TRUE
B39: FIPS | C39: =($H$8-H6)/(SQRT(($M$8/50)+(M6/50))) -> -5.4093484 | D39: =($H$18-H16)/(SQRT(($M$18/50)+(M16/50))) -> 3.2452134 | E39: =($H$28-H26)/(SQRT(($M$28/50)+(M26/50))) -> 12.799594 | H39: FIPS | I39: =49*(($M$8+M6)^2)/($M$8^2+M6^2) -> 52.649928 | J39: =49*(($M$18+M16^2)/($M$18^2+M16^2)) -> 0.10561189 | K39: =49*(($M$28+M26)^2)/($M$28^2+M26^2) -> 51.068419 | N39: FIPS | O39: 0 | P39: 0.7239 | Q39: 0 | T39: FIPS | U39: =IF(O39>=0.05, FALSE, TRUE) -> TRUE | V39: =IF(P39>=0.05, FALSE, TRUE) -> FALSE | W39: =IF(Q39>=0.05, FALSE, TRUE) -> TRUE
B40: Hybrid PSO | C40: =($H$8-H7)/(SQRT(($M$8/50)+(M7/50))) -> 1.9820458 | D40: =($H$18-H17)/(SQRT(($M$18/50)+(M17/50))) -> 1.4392886 | E40: =($H$28-H27)/(SQRT(($M$28/50)+(M27/50))) -> -6.3873332 | H40: Hybrid PSO | I40: =49*(($M$8+M7)^2)/($M$8^2+M7^2) -> 97.807514 | J40: =49*(($M$18+M17^2)/($M$18^2+M17^2)) -> 19.339559 | K40: =49*(($M$28+M27)^2)/($M$28^2+M27^2) -> 81.992497 | N40: Hybrid PSO | O40: 0.05 | P40: 0.1658 | Q40: 0 | T40: Hybrid PSO | U40: =IF(O40>=0.05, FALSE, TRUE) -> FALSE | V40: =IF(P40>=0.05, FALSE, TRUE) -> FALSE | W40: =IF(Q40>=0.05, FALSE, TRUE) -> TRUE
A41: Rastrigin | B41: GA | C41: =($I$8-I4)/(SQRT(($N$8/50)+(N4/50))) -> 7.3081292 | D41: =($I$18-I14)/(SQRT(($N$18/50)+(N14/50))) -> 8.4042223 | E41: =($I$28-I24)/(SQRT(($N$28/50)+(N24/50))) -> -23.025389 | G41: Rastrigin | H41: GA | I41: =49*(($N$8+N4)^2)/($N$8^2+N4^2) -> 69.687743 | J41: =49*(($N$18+N14^2)/($N$18^2+N14^2)) -> 21.067297 | K41: =49*(($N$28+N24)^2)/($N$28^2+N24^2) -> 63.306001 | M41: Rastrigin | N41: GA | O41: 0 | P41: 0 | Q41: 0 | S41: Rastrigin | T41: GA | U41: =IF(O41>=0.05, FALSE, TRUE) -> TRUE | V41: =IF(P41>=0.05, FALSE, TRUE) -> TRUE | W41: =IF(Q41>=0.05, FALSE, TRUE) -> TRUE
B42: PSO | C42: =($I$8-I5)/(SQRT(($N$8/50)+(N5/50))) -> 5.2022249 | D42: =($I$18-I15)/(SQRT(($N$18/50)+(N15/50))) -> -0.18982422 | E42: =($I$28-I25)/(SQRT(($N$28/50)+(N25/50))) -> 14.008134 | H42: PSO | I42: =49*(($N$8+N5)^2)/($N$8^2+N5^2) -> 77.729346 | J42: =49*(($N$18+N15^2)/($N$18^2+N15^2)) -> 40.341608 | K42: =49*(($N$28+N25)^2)/($N$28^2+N25^2) -> 89.039502 | N42: PSO | O42: 0 | P42: 0.85 | Q42: 0 | T42: PSO | U42: =IF(O42>=0.05, FALSE, TRUE) -> TRUE | V42: =IF(P42>=0.05, FALSE, TRUE) -> FALSE | W42: =IF(Q42>=0.05, FALSE, TRUE) -> TRUE
B43: FIPS | C43: =($I$8-I6)/(SQRT(($N$8/50)+(N6/50))) -> 7.5297325 | D43: =($I$18-I16)/(SQRT(($N$18/50)+(N16/50))) -> 18.460735 | E43: =($I$28-I26)/(SQRT(($N$28/50)+(N26/50))) -> 39.974045 | H43: FIPS | I43: =49*(($N$8+N6)^2)/($N$8^2+N6^2) -> 66.640105 | J43: =49*(($N$18+N16^2)/($N$18^2+N16^2)) -> 0.80954366 | K43: =49*(($N$28+N26)^2)/($N$28^2+N26^2) -> 52.141702 | N43: FIPS | O43: 0 | P43: 0.058 | Q43: 0 | T43: FIPS | U43: =IF(O43>=0.05, FALSE, TRUE) -> TRUE | V43: =IF(P43>=0.05, FALSE, TRUE) -> FALSE | W43: =IF(Q43>=0.05, FALSE, TRUE) -> TRUE
B44: Hybrid PSO | C44: =($I$8-I7)/(SQRT(($N$8/50)+(N7/50))) -> 1.4582528 | D44: =($I$18-I17)/(SQRT(($N$18/50)+(N17/50))) -> 0.33901315 | E44: =($I$28-I27)/(SQRT(($N$28/50)+(N27/50))) -> -2.6850173 | H44: Hybrid PSO | I44: =49*(($N$8+N7)^2)/($N$8^2+N7^2) -> 95.726558 | J44: =49*(($N$18+N17^2)/($N$18^2+N17^2)) -> 30.580884 | K44: =49*(($N$28+N27)^2)/($N$28^2+N27^2) -> 95.248578 | N44: Hybrid PSO | O44: 0.1475 | P44: 0.736 | Q44: 0.008 | T44: Hybrid PSO | U44: =IF(O44>=0.05, FALSE, TRUE) -> FALSE | V44: =IF(P44>=0.05, FALSE, TRUE) -> FALSE | W44: =IF(Q44>=0.05, FALSE, TRUE) -> TRUE
M48: better
M49: 1-sided p | N49: Algorithm | O49: D=5 | P49: D=30 | Q49: D=100 | S49: Comp. Perf | T49: Algorithm | U49: D=5 | V49: D=30 | W49: D=100
M50: Sphere | N50: GA | O50: 1 | P50: 0.01 | Q50: 0 | S50: Sphere | T50: GA | U50: =IF(O50>=0.05, "WORSE", "BETTER") -> WORSE | V50: =IF(P50>=0.05, "WORSE", "BETTER") -> BETTER | W50: =IF(Q50>=0.05, "WORSE", "BETTER") -> BETTER
N51: PSO | O51: 1 | P51: 1 | Q51: 0.018 | T51: PSO | U51: =IF(O51>=0.05, "WORSE", "BETTER") -> WORSE | V51: =IF(P51>=0.05, "WORSE", "BETTER") -> WORSE | W51: =IF(Q51>=0.05, "WORSE", "BETTER") -> BETTER
...
